<?xml version="1.0" ?>
<!-- =================================================================================== -->
<!-- |    This document was autogenerated by xacro from ofa_moveit_config/config/ofa_robot.urdf.xacro | -->
<!-- |    EDITING THIS FILE BY HAND IS NOT RECOMMENDED                                 | -->
<!-- =================================================================================== -->
<robot name="ofa_robot">
  <material name="black">
    <color rgba="0 0 0 1.0"/>
  </material>
  <material name="dark_grey">
    <color rgba="0 0 0.6078431372549019 1.0"/>
  </material>
  <material name="blue">
    <color rgba="0 0 0.7843137254901961 1.0"/>
  </material>
  <material name="green">
    <color rgba="0 0.7843137254901961 0 1.0"/>
  </material>
  <material name="grey">
    <color rgba="0.19607843137254902 0.19607843137254902 0.19607843137254902 1.0"/>
  </material>
  <material name="orange">
    <color rgba="1.0 0.4235294117647059 0.0392156862745098 1.0"/>
  </material>
  <material name="brown">
    <color rgba="0.8705882352941177 0.8117647058823529 0.7647058823529411 1.0"/>
  </material>
  <material name="red">
    <color rgba="0.7843137254901961 0 0 1.0"/>
  </material>
  <material name="white">
    <color rgba="1.0 1.0 1.0 1.0"/>
  </material>
  <link name="world"/>
  <joint name="base_joint" type="fixed">
    <origin rpy="0 0 0" xyz="0 0 0.75"/>
    <parent link="world"/>
    <child link="base_link"/>
  </joint>
  <link name="base_link">
    <visual>
      <origin rpy="0 0 0" xyz="0 0 -0.036"/>
      <geometry>
        <box size="1.216 0.06 0.072"/>
      </geometry>
      <material name="blue"/>
    </visual>
    <collision>
      <origin rpy="0 0 0" xyz="0 0 -0.036"/>
      <geometry>
        <box size="1.216 0.06 0.072"/>
      </geometry>
    </collision>
    <!-- Top (Frame) -->
    <collision>
      <origin rpy="0 0 0" xyz="0 0 -0.015"/>
      <geometry>
        <box size="1.3 1.0 0.03"/>
      </geometry>
    </collision>
    <!-- Side (Wheels) -->
    <collision>
      <origin rpy="0 0 0" xyz="0 -0.505 -0.375"/>
      <geometry>
        <box size="1.3 0.01 0.75"/>
      </geometry>
    </collision>
    <collision>
      <origin rpy="0 0 0" xyz="0 0.505 -0.375"/>
      <geometry>
        <box size="1.3 0.01 0.75"/>
      </geometry>
    </collision>
    <!-- Bottom (Ground) -->
    <collision>
      <origin rpy="0 0 0" xyz="0 0 -0.755"/>
      <geometry>
        <box size="1.3 1.0 0.01"/>
      </geometry>
    </collision>
  </link>
  <joint name="joint1" type="prismatic">
    <origin rpy="0 0 0" xyz="-0.5106000000000002 0 -0.134"/>
    <parent link="base_link"/>
    <child link="link1"/>
    <axis xyz="-1 0 0"/>
    <limit effort="100" lower="-0.95" upper="0.01" velocity="1.0"/>
  </joint>
  <link name="link1">
    <visual>
      <origin rpy="0 1.5707963267948966 0" xyz="0 0 0"/>
      <geometry>
        <cylinder length="0.05025" radius="0.0445"/>
      </geometry>
      <material name="black"/>
    </visual>
    <collision>
      <origin rpy="0 1.5707963267948966 0" xyz="0 0 0"/>
      <geometry>
        <cylinder length="0.05025" radius="0.0445"/>
      </geometry>
    </collision>
  </link>
  <joint name="camera_shield_joint" type="fixed">
    <origin rpy="0 0 0" xyz="-0.09267500000000001 -0.044 0.062"/>
    <parent link="link1"/>
    <child link="camera_shield_link"/>
  </joint>
  <link name="camera_shield_link">
    <visual>
      <origin rpy="0 0 0" xyz="0 -0.059 -0.04"/>
      <geometry>
        <box size="0.048 0.002 0.08"/>
      </geometry>
      <material name="grey"/>
    </visual>
    <visual>
      <origin rpy="0 0 0" xyz="0 0.059 -0.04"/>
      <geometry>
        <box size="0.048 0.002 0.08"/>
      </geometry>
      <material name="grey"/>
    </visual>
    <collision>
      <origin rpy="0 0 0" xyz="0 -0.059 -0.04"/>
      <geometry>
        <box size="0.048 0.002 0.08"/>
      </geometry>
    </collision>
    <collision>
      <origin rpy="0 0 0" xyz="0 0.059 -0.04"/>
      <geometry>
        <box size="0.048 0.002 0.08"/>
      </geometry>
    </collision>
  </link>
  <joint name="camera_joint" type="fixed">
    <origin rpy="0 0 0" xyz="0 0.00045 -0.00615"/>
    <parent link="camera_shield_link"/>
    <child link="camera_link"/>
  </joint>
  <link name="camera_link">
    <visual>
      <origin rpy="0 0 0" xyz="0 0 -0.032625"/>
      <geometry>
        <box size="0.04026 0.11526 0.06525"/>
      </geometry>
      <material name="grey"/>
    </visual>
    <collision>
      <origin rpy="0 0 0" xyz="0 0 -0.032625"/>
      <geometry>
        <box size="0.04026 0.11526 0.06525"/>
      </geometry>
    </collision>
  </link>
  <joint name="camera_color_joint" type="fixed">
    <origin rpy="3.141592653589793 0 1.5707963267948966" xyz="0 0.03 -0.05659361"/>
    <parent link="camera_link"/>
    <child link="camera_color_frame"/>
  </joint>
  <link name="camera_color_frame"/>
  <joint name="joint2" type="revolute">
    <origin rpy="0 0 0" xyz="0.057625 0 0"/>
    <parent link="link1"/>
    <child link="link2"/>
    <axis xyz="1 0 0"/>
    <limit effort="100" lower="-1.57" upper="1.57" velocity="5.0"/>
  </joint>
  <link name="link2">
    <visual>
      <origin rpy="0 0 0" xyz="0 0 -0.181"/>
      <geometry>
        <cylinder length="0.362" radius="0.0225"/>
      </geometry>
      <material name="orange"/>
    </visual>
    <collision>
      <origin rpy="0 0 0" xyz="0 0 -0.181"/>
      <geometry>
        <cylinder length="0.362" radius="0.0225"/>
      </geometry>
    </collision>
  </link>
  <joint name="joint2_motor" type="fixed">
    <origin rpy="0 0 0" xyz="-0.057625 0 -0.362"/>
    <parent link="link2"/>
    <child link="link2_motor"/>
  </joint>
  <link name="link2_motor">
    <visual>
      <origin rpy="0 1.5707963267948966 0" xyz="0 0 0"/>
      <geometry>
        <cylinder length="0.05025" radius="0.0445"/>
      </geometry>
      <material name="black"/>
    </visual>
    <collision>
      <origin rpy="0 1.5707963267948966 0" xyz="0 0 0"/>
      <geometry>
        <cylinder length="0.05025" radius="0.0445"/>
      </geometry>
    </collision>
  </link>
  <joint name="joint3" type="revolute">
    <origin rpy="3.141592653589793 0 0" xyz="-0.057625 0 0"/>
    <parent link="link2_motor"/>
    <child link="link3"/>
    <axis xyz="-1 0 0"/>
    <limit effort="100" lower="-3.14" upper="3.14" velocity="5.0"/>
  </joint>
  <link name="link3">
    <visual>
      <origin rpy="0 0 0" xyz="0 0 -0.0805"/>
      <geometry>
        <cylinder length="0.161" radius="0.0225"/>
      </geometry>
      <material name="orange"/>
    </visual>
    <visual>
      <origin rpy="0 0 0" xyz="0 0 -0.241"/>
      <geometry>
        <cylinder length="0.16" radius="0.013"/>
      </geometry>
      <material name="orange"/>
    </visual>
    <visual>
      <origin rpy="0 0 0" xyz="0 0 -0.338"/>
      <geometry>
        <cylinder length="0.034" radius="0.003"/>
      </geometry>
      <material name="orange"/>
    </visual>
    <collision>
      <origin rpy="0 0 0" xyz="0 0 -0.0805"/>
      <geometry>
        <cylinder length="0.161" radius="0.0225"/>
      </geometry>
    </collision>
    <collision>
      <origin rpy="0 0 0" xyz="0 0 -0.241"/>
      <geometry>
        <cylinder length="0.16" radius="0.013"/>
      </geometry>
    </collision>
    <collision>
      <origin rpy="0 0 0" xyz="0 0 -0.338"/>
      <geometry>
        <cylinder length="0.034" radius="0.003"/>
      </geometry>
    </collision>
  </link>
  <joint name="joint3_end" type="fixed">
    <origin rpy="0 0 0" xyz="0 0 -0.355"/>
    <parent link="link3"/>
    <child link="eef_link"/>
  </joint>
  <link name="eef_link"/>
  <!-- Linear axis -->
  <ros2_control name="linear_axis" type="system">
    <hardware>
      <plugin>teknic_hardware/TeknicSystemHardware</plugin>
    </hardware>
    <joint name="joint1">
      <param name="port">/dev/ttyXRUSB0</param>
      <param name="node">0</param>
      <param name="acc_limit">2.0</param>
      <param name="vel_limit">2.0</param>
      <param name="feed_constant">0.078</param>
      <param name="peak_torque">4.01</param>
      <param name="homing">1</param>
      <command_interface name="position"/>
      <command_interface name="velocity"/>
      <state_interface name="position"/>
      <state_interface name="velocity"/>
      <state_interface name="effort"/>
    </joint>
  </ros2_control>
  <!-- 2 DoF arm -->
  <ros2_control name="arm_2dof" type="system">
    <hardware>
      <plugin>cubemars_hardware/CubeMarsSystemHardware</plugin>
      <param name="can_interface">can0</param>
    </hardware>
    <joint name="joint2">
      <param name="can_id">90</param>
      <param name="pole_pairs">21</param>
      <param name="gear_ratio">10</param>
      <param name="kt">0.123</param>
      <param name="enc_off">-0.084</param>
      <param name="trq_limit">30</param>
      <command_interface name="position"/>
      <command_interface name="velocity"/>
      <command_interface name="acceleration"/>
      <command_interface name="effort"/>
      <state_interface name="position"/>
      <state_interface name="velocity"/>
      <state_interface name="effort"/>
      <state_interface name="temperature"/>
    </joint>
    <joint name="joint3">
      <param name="can_id">91</param>
      <param name="pole_pairs">21</param>
      <param name="gear_ratio">10</param>
      <param name="kt">0.123</param>
      <param name="enc_off">-0.084</param>
      <param name="trq_limit">20</param>
      <command_interface name="position"/>
      <command_interface name="velocity"/>
      <command_interface name="acceleration"/>
      <command_interface name="effort"/>
      <state_interface name="position"/>
      <state_interface name="velocity"/>
      <state_interface name="effort"/>
      <state_interface name="temperature"/>
    </joint>
  </ros2_control>
</robot>
